[exception:handle_uncaught_exception] [ERROR]- Internal Server Error: /t09/index
Traceback (most recent call last):
  File "/home/lisi/.virtualenvs/py1808/lib/python3.5/site-packages/django/core/handlers/exception.py", line 41, in inner
    response = get_response(request)
  File "/home/lisi/.virtualenvs/py1808/lib/python3.5/site-packages/django/core/handlers/base.py", line 187, in _get_response
    response = self.process_exception_by_middleware(e, request)
  File "/home/lisi/.virtualenvs/py1808/lib/python3.5/site-packages/django/core/handlers/base.py", line 185, in _get_response
    response = wrapped_callback(request, *callback_args, **callback_kwargs)
  File "/home/lisi/teach1808/day09/day09/t09/views.py", line 10, in index
    a/6
NameError: name 'a' is not defined
[exception:handle_uncaught_exception] [ERROR]- Internal Server Error: /t09/index
Traceback (most recent call last):
  File "/home/lisi/.virtualenvs/py1808/lib/python3.5/site-packages/django/core/handlers/exception.py", line 41, in inner
    response = get_response(request)
  File "/home/lisi/.virtualenvs/py1808/lib/python3.5/site-packages/django/core/handlers/base.py", line 187, in _get_response
    response = self.process_exception_by_middleware(e, request)
  File "/home/lisi/.virtualenvs/py1808/lib/python3.5/site-packages/django/core/handlers/base.py", line 185, in _get_response
    response = wrapped_callback(request, *callback_args, **callback_kwargs)
  File "/home/lisi/teach1808/day09/day09/t09/views.py", line 10, in index
    a131
NameError: name 'a131' is not defined
